import { Component } from "react";
import type { ErrorInfo, ReactNode } from "react";

interface Props {
  children: ReactNode;
  fallback?: ReactNode;
}

interface State {
  hasError: boolean;
  error?: Error;
}

class ErrorBoundary extends Component<Props, State> {
  constructor(props: Props) {
    super(props);
    this.state = { hasError: false };
  }

  static getDerivedStateFromError(error: Error): State {
    return { hasError: true, error };
  }

  componentDidCatch(error: Error, errorInfo: ErrorInfo) {
    console.error("Error caught by boundary:", error, errorInfo);
    // In production, send to error tracking service (e.g., Sentry)
  }

  render() {
    if (this.state.hasError) {
      if (this.props.fallback) {
        return this.props.fallback;
      }

      return (
        <div className="min-h-screen flex items-center justify-center bg-gray-100">
          <div className="max-w-md p-6 bg-white rounded-lg shadow-md">
            <h1 className="text-2xl font-bold text-red-600 mb-4">
              Something went wrong
            </h1>
            <p className="text-gray-700 mb-4">
              We're sorry, but something unexpected happened. Please try
              refreshing the page.
            </p>
            <button
              onClick={() => window.location.reload()}
              className="bg-blue-500 text-white px-4 py-2 rounded hover:bg-blue-600"
            >
              Refresh Page
            </button>
            {process.env.NODE_ENV === "development" && this.state.error && (
              <pre className="mt-4 p-4 bg-gray-100 rounded text-xs overflow-auto">
                {this.state.error.message}
              </pre>
            )}
          </div>
        </div>
      );
    }

    return this.props.children;
  }
}

export default ErrorBoundary;
